Python 3.6.4 (v3.6.4:d48eceb, Dec 19 2017, 06:54:40) [MSC v.1900 64 bit (AMD64)] on win32
Type "help", "copyright", "credits" or "license" for more information.
>>> import tensorflow as tf
Traceback (most recent call last):
  File "C:\Users\Raymond Yang\AppData\Local\Programs\Python\Python36\lib\site-packages\tensorflow\python\pywrap_tensorflow_internal.py", line 14, in swig_import_helper
    return importlib.import_module(mname)
  File "C:\Users\Raymond Yang\AppData\Local\Programs\Python\Python36\lib\importlib\__init__.py", line 126, in import_module
    return _bootstrap._gcd_import(name[level:], package, level)
  File "<frozen importlib._bootstrap>", line 994, in _gcd_import
  File "<frozen importlib._bootstrap>", line 971, in _find_and_load
  File "<frozen importlib._bootstrap>", line 955, in _find_and_load_unlocked
  File "<frozen importlib._bootstrap>", line 658, in _load_unlocked
  File "<frozen importlib._bootstrap>", line 571, in module_from_spec
  File "<frozen importlib._bootstrap_external>", line 922, in create_module
  File "<frozen importlib._bootstrap>", line 219, in _call_with_frames_removed
ImportError: DLL load failed: A dynamic link library (DLL) initialization routine failed.

During handling of the above exception, another exception occurred:

Traceback (most recent call last):
  File "C:\Users\Raymond Yang\AppData\Local\Programs\Python\Python36\lib\site-packages\tensorflow\python\pywrap_tensorflow.py", line 58, in <module>
    from tensorflow.python.pywrap_tensorflow_internal import *
  File "C:\Users\Raymond Yang\AppData\Local\Programs\Python\Python36\lib\site-packages\tensorflow\python\pywrap_tensorflow_internal.py", line 17, in <module>
    _pywrap_tensorflow_internal = swig_import_helper()
  File "C:\Users\Raymond Yang\AppData\Local\Programs\Python\Python36\lib\site-packages\tensorflow\python\pywrap_tensorflow_internal.py", line 16, in swig_import_helper
    return importlib.import_module('_pywrap_tensorflow_internal')
  File "C:\Users\Raymond Yang\AppData\Local\Programs\Python\Python36\lib\importlib\__init__.py", line 126, in import_module
    return _bootstrap._gcd_import(name[level:], package, level)
ModuleNotFoundError: No module named '_pywrap_tensorflow_internal'

During handling of the above exception, another exception occurred:

Traceback (most recent call last):
  File "<stdin>", line 1, in <module>
  File "C:\Users\Raymond Yang\AppData\Local\Programs\Python\Python36\lib\site-packages\tensorflow\__init__.py", line 22, in <module>
    from tensorflow.python import pywrap_tensorflow  # pylint: disable=unused-import
  File "C:\Users\Raymond Yang\AppData\Local\Programs\Python\Python36\lib\site-packages\tensorflow\python\__init__.py", line 49, in <module>
    from tensorflow.python import pywrap_tensorflow
  File "C:\Users\Raymond Yang\AppData\Local\Programs\Python\Python36\lib\site-packages\tensorflow\python\pywrap_tensorflow.py", line 74, in <module>
    raise ImportError(msg)
ImportError: Traceback (most recent call last):
  File "C:\Users\Raymond Yang\AppData\Local\Programs\Python\Python36\lib\site-packages\tensorflow\python\pywrap_tensorflow_internal.py", line 14, in swig_import_helper
    return importlib.import_module(mname)
  File "C:\Users\Raymond Yang\AppData\Local\Programs\Python\Python36\lib\importlib\__init__.py", line 126, in import_module
    return _bootstrap._gcd_import(name[level:], package, level)
  File "<frozen importlib._bootstrap>", line 994, in _gcd_import
  File "<frozen importlib._bootstrap>", line 971, in _find_and_load
  File "<frozen importlib._bootstrap>", line 955, in _find_and_load_unlocked
  File "<frozen importlib._bootstrap>", line 658, in _load_unlocked
  File "<frozen importlib._bootstrap>", line 571, in module_from_spec
  File "<frozen importlib._bootstrap_external>", line 922, in create_module
  File "<frozen importlib._bootstrap>", line 219, in _call_with_frames_removed
ImportError: DLL load failed: A dynamic link library (DLL) initialization routine failed.

During handling of the above exception, another exception occurred:

Traceback (most recent call last):
  File "C:\Users\Raymond Yang\AppData\Local\Programs\Python\Python36\lib\site-packages\tensorflow\python\pywrap_tensorflow.py", line 58, in <module>
    from tensorflow.python.pywrap_tensorflow_internal import *
  File "C:\Users\Raymond Yang\AppData\Local\Programs\Python\Python36\lib\site-packages\tensorflow\python\pywrap_tensorflow_internal.py", line 17, in <module>
    _pywrap_tensorflow_internal = swig_import_helper()
  File "C:\Users\Raymond Yang\AppData\Local\Programs\Python\Python36\lib\site-packages\tensorflow\python\pywrap_tensorflow_internal.py", line 16, in swig_import_helper
    return importlib.import_module('_pywrap_tensorflow_internal')
  File "C:\Users\Raymond Yang\AppData\Local\Programs\Python\Python36\lib\importlib\__init__.py", line 126, in import_module
    return _bootstrap._gcd_import(name[level:], package, level)
ModuleNotFoundError: No module named '_pywrap_tensorflow_internal'


Failed to load the native TensorFlow runtime.

See https://www.tensorflow.org/install/install_sources#common_installation_problems

for some common reasons and solutions.  Include the entire stack trace
above this error message when asking for help.
>>>